Workbook

Sheet Phụ lục I
A1: Phụ lục I: CHI TIẾT DANH MỤC THUỐC BỔ SUNG TẠI BỆNH VIỆN ĐÀ NẴNG NĂM 2026
A2: (Đính kèm Thông báo số /TB-BVĐN ngày / /2026 của Bệnh viện Đà Nẵng)
A4: STT | B4: TT20 | C4: Nhóm TCKT | D4: Tên thuốc | E4: Tên hoạt chất | F4: Nồng độ, hàm lượng | G4: Đường dùng | H4: Dạng bào chế | I4: Quy cách đóng gói | J4: Hạn dùng (tháng) | K4: SĐK hoặc số GPNK | L4: Cơ sở sản xuất | M4: Nước sản xuất | N4: Đơn vị tính | O4: Đơn giá | P4: Số lượng | Q4: Số lượng tuỳ chọn mua thêm | R4: Quyết định trúng thầu | S4: Lưu ý khi kê đơn | T4: Thuốc hiếm theo Thông tư số 26/2019/TT-BYT ngày 30/8/2019 | U4: Chỉ định phòng, chẩn đoán, điều trị bệnh hiếm gặp | V4: Tên nhà thầu
A5: 1 | B5: 563 | C5: Nhóm 2 | D5: Clopalvix | E5: Clopidogrel (tương đương clopidogrel bisulfat 97,86mg) | F5: 75mg | G5: Uống | H5: Viên nén bao phim | I5: Hộp 05 vỉ x 14 viên | K5: 893110657224 | L5: Công ty cổ phần dược phẩm Boston Việt Nam | M5: Việt Nam | N5: Viên | O5: 378 | P5: 8200 | R5: 165/QĐ-TTMS
A6: 2 | B6: 5 | C6: Nhóm 4 | D6: Diazepam 10mg/2ml | E6: Diazepam | F6: 10mg/2ml | G6: Tiêm | H6: Dung dịch tiêm | I6: Hộp 10 ống x 2ml | J6: 36 tháng | K6: 893112683724 (SĐK cũ: VD-25308-16) | L6: Công ty cổ phần dược phẩm Trung ương Vidipha | M6: Việt Nam | N6: Ống | O6: 8000 | P6: 3990 | Q6: =ROUNDDOWN((P6*30%),0) -> 1197 | R6: 449/QĐ-BVĐN | V6: CÔNG TY CỔ PHẦN DƯỢC PHẨM TRUNG ƯƠNG CPC1
A7: 3 | B7: 7 | C7: Nhóm 5 | D7: Thuốc tiêm Fentanyl citrate | E7: Fentanyl | F7: 500mcg | G7: Tiêm | H7: Dung dịch tiêm bắp, tiêm tĩnh mạch, truyền tĩnh mạch, tiêm ngoài màng cứng | I7: Hộp 2 ống x 10ml; Hộp 5 ống x 10ml | J7: 48 tháng | K7: 690111337925 (VN-18482-14) | L7: Yichang Humanwell Pharmaceutical Co.,Ltđ | M7: China | N7: Ống | O7: 28000 | P7: 15720 | Q7: =ROUNDDOWN((P7*30%),0) -> 4716 | R7: 449/QĐ-BVĐN | V7: CÔNG TY CỔ PHẦN DƯỢC PHẨM TRUNG ƯƠNG CODUPHA
A8: 4 | B8: 16 | C8: Nhóm 1 | D8: Opiphine | E8: Morphin | F8: Morphin 7,52mg hoặc 10mg dưới dạng muối | G8: Tiêm | H8: Dung dịch tiêm | I8: Hộp 10 ống 1ml | J8: 36 tháng | K8: 400111072223 (VN-19415-15) | L8: Siegfried Hameln GmbH | M8: Germany | N8: Ống | O8: 48968 | P8: 10350 | Q8: =ROUNDDOWN((P8*30%),0) -> 3105 | R8: 449/QĐ-BVĐN | V8: CÔNG TY CỔ PHẦN DƯỢC PHẨM TRUNG ƯƠNG CODUPHA
A9: 5 | B9: 20 | C9: Nhóm 1 | D9: Alcaine 0,5% | E9: Proparacain hydroclorid | F9: 0,5% (w/v) | G9: Nhỏ mắt | H9: Dung dịch nhỏ mắt | I9: Hộp 1 lọ 15ml | J9: 30 tháng | K9: 540110001624 | L9: Novartis Manufacturing NV | M9: Bỉ | N9: Lọ | O9: 39380 | P9: 120 | Q9: =ROUNDDOWN((P9*30%),0) -> 36 | R9: 449/QĐ-BVĐN | V9: CÔNG TY CỔ PHẦN DƯỢC - THIẾT BỊ Y TẾ ĐÀ NẴNG
A10: 6 | B10: 22 | C10: Nhóm 4 | D10: Vinropin 0,5% | E10: Ropivacain hydroclorid | F10: 50mg/10ml | G10: Tiêm | H10: Dung dịch tiêm | I10: Hộp 1 vỉ x 5 ống x 10ml | J10: 36 tháng | K10: 893114283224 | L10: Công ty Cổ phần Dược phẩm Vĩnh Phúc | M10: Việt Nam | N10: Ống | O10: 90000 | P10: 2000 | Q10: =ROUNDDOWN((P10*30%),0) -> 600 | R10: 449/QĐ-BVĐN | V10: CÔNG TY CỔ PHẦN DƯỢC PHẨM VĨNH PHÚC
A11: 7 | B11: 30 | C11: Nhóm 1 | D11: Rocuronium Kabi 10mg/ml | E11: Rocuronium bromid | F11: (10mg/ml) x 5ml | G11: Tiêm hoặc Truyền tĩnh mạch | H11: Dung dịch tiêm hoặc tiêm truyền | I11: Hộp 10 lọ x 5ml | J11: 24 tháng | K11: VN-22745-21 | L11: Fresenius Kabi Austria GmbH | M11: Áo | N11: Lọ | O11: 87300 | P11: 20400 | Q11: =ROUNDDOWN((P11*30%),0) -> 6120 | R11: 449/QĐ-BVĐN | V11: CÔNG TY CỔ PHẦN DƯỢC LIỆU TRUNG ƯƠNG 2
A12: 8 | B12: 30 | C12: Nhóm 4 | D12: Rocuronium 50mg | E12: Rocuronium bromid | F12: 50mg/5ml | G12: Tiêm/Tiêm truyền | H12: Dung dịch tiêm | I12: Hộp 4 vỉ, 10 vỉ x 5 ống x 5ml | J12: 36 tháng | K12: VD-35273-21 | L12: Công ty Cổ phần Dược phẩm Vĩnh Phúc | M12: Việt Nam | N12: Ống | O12: 41000 | P12: 13300 | Q12: =ROUNDDOWN((P12*30%),0) -> 3990 | R12: 449/QĐ-BVĐN | V12: CÔNG TY CỔ PHẦN DƯỢC PHẨM VĨNH PHÚC
A13: 9 | B13: 34 | C13: Nhóm 4 | D13: VINSINAT 10 mg | E13: Aescin | F13: 10mg | G13: Tiêm | H13: Thuốc tiêm đông khô | I13: Hộp 5 lọ + 5 ống dung môi; Hộp 5 lọ, 10 lọ | J13: Lọ thuốc tiêm đông khô: 36 tháng, Ống dung môi: 36 tháng | K13: VD-36171-22 | L13: Công ty cổ phần dược phẩm Vĩnh Phúc | M13: Việt Nam | N13: Lọ | O13: 84000 | P13: 4000 | Q13: =ROUNDDOWN((P13*30%),0) -> 1200 | R13: 449/QĐ-BVĐN | V13: CÔNG TY TNHH DP-TBYT BẢO MINH
A14: 10 | B14: 37 | C14: Nhóm 1 | D14: Voltaren 75mg/3ml | E14: Diclofenac | F14: 75mg/3ml | G14: Tiêm | H14: Dung dịch thuốc tiêm | I14: Hộp 1 vỉ x 5 ống 3ml | J14: 24 tháng | K14: VN-20041-16 (Có QĐ gia hạn số 853/QĐ-QLD ngày 30/12/2022) | L14: Lek Pharmaceuticals d.d. | M14: Slovenia | N14: Ống | O14: 19698 | P14: 1460 | Q14: =ROUNDDOWN((P14*30%),0) -> 438 | R14: 449/QĐ-BVĐN | V14: CÔNG TY CỔ PHẦN DƯỢC - THIẾT BỊ Y TẾ ĐÀ NẴNG
A15: 11 | B15: 77 | C15: Nhóm 1 | D15: Colchicina Seid 1mg Tablet | E15: Colchicin | F15: 1 mg | G15: Uống | H15: Viên nén | I15: Hộp 2 vỉ x 20 viên | J15: 60 tháng | K15: 840115989624 (VN-22254-19) | L15: Seid, S.A | M15: Spain | N15: Viên | O15: 5400 | P15: 1500 | Q15: =ROUNDDOWN((P15*30%),0) -> 450 | R15: 449/QĐ-BVĐN | V15: CÔNG TY TNHH THƯƠNG MẠI & DƯỢC PHẨM TÂM TOÀN PHÁT
A16: 12 | B16: 77 | C16: Nhóm 4 | D16: GOUTCOLCIN | E16: Colchicin | F16: 1mg | G16: Uống | H16: Viên nén | I16: Hộp 2 vỉ x 20 viên | J16: 24 tháng | K16: 893115430624 (VD-24115-16) | L16: CN Cty CPDP Agimexpharm - Nhà máy SX DP Agimexpharm | M16: Việt Nam | N16: Viên | O16: 600 | P16: 10410 | Q16: =ROUNDDOWN((P16*30%),0) -> 3123 | R16: 449/QĐ-BVĐN | V16: CÔNG TY CP DƯỢC PHẨM AGIMEXPHARM
A17: 13 | B17: 106 | C17: Nhóm 1 | D17: Telfast HD | E17: Fexofenadin | F17: 180mg | G17: Uống | H17: Viên nén bao phim | I17: Hộp 1 vỉ x 10 viên; Hộp 3 vỉ x 10 viên | J17: 36 tháng | K17: 893100314023 | L17: Công ty Cổ phần Sanofi Việt Nam | M17: Việt Nam | N17: Viên | O17: 8028 | P17: 4840 | Q17: =ROUNDDOWN((P17*30%),0) -> 1452 | R17: 449/QĐ-BVĐN | V17: CÔNG TY TNHH DƯỢC PHẨM VÀ TRANG THIẾT BỊ Y TẾ HOÀNG ĐỨC
... A30: 26 | B30: 241 | C30: Nhóm 4 | D30: Sulfadiazin Bạc | E30: Sulfadiazin bạc | F30: 1% (w/w) x 200g | G30: Dùng ngoài | H30: Kem bôi da | I30: Hộp 200g | J30: 36 tháng | K30: 893100130725 (VD-28280-17) | L30: Công ty CP Dược Medipharco | M30: Việt Nam | N30: Hộp | O30: 132000 | P30: 1560 | Q30: =ROUNDDOWN((P30*30%),0) -> 468 | R30: 449/QĐ-BVĐN | V30: LIÊN DANH MEDIPHARCO VÀ LƯƠNG ANH
A31: 27 | B31: 278 | C31: Nhóm 2 | D31: Myvelpa | E31: Sofosbuvir + velpatasvir | F31: Velpatasvir 100mg, Sofosbuvir 400mg | G31: Uống | H31: Viên nén bao phim | I31: Hộp 1 lọ x 28 viên | J31: 36 tháng | K31: 890110196823 (SĐK cũ: VN3-242-19) | L31: Mylan Laboratories Limited | M31: India | N31: Viên | O31: 194000 | P31: 3192 | Q31: =ROUNDDOWN((P31*30%),0) -> 957 | R31: 449/QĐ-BVĐN | S31: =VLOOKUP(B31,[1]GỐC!$B:$F,5,0) -> Quỹ bảo hiểm y tế thanh toán 50%. | V31: CÔNG TY CỔ PHẦN BẢO TOÀN PHARMA
A32: 28 | B32: 288 | C32: Nhóm 5 | D32: Amphotret | E32: Amphotericin B* | F32: 50mg | G32: Tiêm truyền | H32: Bột đông khô pha tiêm, truyền tĩnh mạch | I32: Hộp 1 lọ, Lọ bột đông khô pha tiêm | J32: 36 tháng | K32: VN-18166-14 | L32: Bharat Serums And Vaccines Limited | M32: India | N32: Lọ | O32: 200000 | P32: 190 | Q32: =ROUNDDOWN((P32*30%),0) -> 57 | R32: 449/QĐ-BVĐN | S32: =VLOOKUP(B32,[1]GỐC!$B:$F,5,0) -> BBHC + Phiếu duyệt KS + Duyệt GĐ | V32: CÔNG TY CỔ PHẦN VILOGI
A33: 29 | B33: 288 | C33: Nhóm 5 | D33: Ampholip | E33: Amphotericin B* | F33: 5 mg/ml | G33: Tiêm | H33: Phức hợp lipid tiêm tĩnh mạch | I33: Hộp 1 Lọ, lọ 10 ml phức hợp lipid tiêm tĩnh mạch kèm kim tiêm lọc vô trùng | J33: 36 tháng | K33: VN-19392-15 | L33: Bharat Serums and Vaccines Limited | M33: Ấn Độ | N33: Lọ | O33: 1800000 | P33: 90 | Q33: =ROUNDDOWN((P33*30%),0) -> 27 | R33: 449/QĐ-BVĐN | S33: =VLOOKUP(B33,[1]GỐC!$B:$F,5,0) -> BBHC + Phiếu duyệt KS + Duyệt GĐ | V33: CÔNG TY TNHH DƯỢC PHẨM VIHAPHA
A34: 30 | B34: 302 | C34: Nhóm 1 | D34: Mycamine for injection 50mg/vial | E34: Micafungin | F34: 50mg | G34: Tiêm | H34: Bột đông khô pha dung dịch tiêm | I34: Hộp 1 lọ | J34: 36 tháng | K34: VN3-102-18 | L34: Astellas Pharma Tech Co., Ltd. Takaoka Plant | M34: Nhật | N34: Lọ | O34: 2388750 | P34: 60 | Q34: =ROUNDDOWN((P34*30%),0) -> 18 | R34: 449/QĐ-BVĐN | S34: =VLOOKUP(B34,[1]GỐC!$B:$F,5,0) -> Quỹ bảo hiểm y tế thanh toán trong điều trị COVID-19 theo hướng dẫn chẩn đoán và điều trị COVID-19 của Bộ Y tế. | V34: CÔNG TY CỔ PHẦN DƯỢC LIỆU TRUNG ƯƠNG 2
A35: 31 | B35: 324 | C35: Nhóm 3 | D35: Turbezid | E35: Rifampicin + isoniazid + pyrazinamid | F35: 150mg +75mg +400 mg | G35: Uống | H35: Viên nén bao phim | I35: Hộp 3 vỉ x 12 viên | J35: 48 tháng | K35: 893110160824 | L35: Công ty cổ phần dược phẩm Nam Hà | M35: Việt Nam | N35: Viên | O35: 2798 | P35: 2400 | Q35: =ROUNDDOWN((P35*30%),0) -> 720 | R35: 449/QĐ-BVĐN | V35: CÔNG TY CỔ PHẦN DƯỢC PHẨM NAM HÀ
A36: 32 | B36: 348 | C36: Nhóm 5 | D36: Bleomycin Bidiphar | E36: Bleomycin | F36: 15U | G36: Tiêm | H36: Bột đông khô pha tiêm | I36: Hộp 1 lọ | J36: 24 tháng | K36: 893114092923 (QLĐB-768-19) | L36: Cơ sở sản xuất: Công ty cổ phần Dược - Trang thiết bị y tế Bình Định (Bidiphar). Nhà máy sản xuất: Chi nhánh Công ty cổ phần Dược - Trang thiết bị y tế Bình Định (Bidiphar) - Nhà máy công nghệ cao Nhơn Hội | M36: Việt Nam | N36: Lọ | O36: 420000 | P36: 150 | Q36: =ROUNDDOWN((P36*30%),0) -> 45 | R36: 449/QĐ-BVĐN | V36: CÔNG TY CỔ PHẦN DƯỢC - TRANG THIẾT BỊ Y TẾ BÌNH ĐỊNH (BIDIPHAR)
A37: 33 | B37: 356 | C37: Nhóm 1 | D37: Alexan | E37: Cytarabin | F37: 50mg/ml | G37: Tiêm truyền tĩnh mạch, tiêm dưới da | H37: Dung dịch tiêm, tiêm truyền | I37: Hộp 1 lọ 10ml | J37: 24 tháng | K37: VN-20580-17 | L37: Fareva Unterach GmbH | M37: Áo | N37: Lọ | O37: 249750 | P37: 1540 | Q37: =ROUNDDOWN((P37*30%),0) -> 462 | R37: 449/QĐ-BVĐN | V37: CÔNG TY CỔ PHẦN DƯỢC LIỆU TRUNG ƯƠNG 2
A38: 34 | B38: 359 | C38: Nhóm 5 | D38: Daunocin | E38: Daunorubicin | F38: 20mg | G38: Tiêm truyền | H38: Bột đông khô pha tiêm | I38: Hộp 1 lọ | J38: 36 tháng | K38: VN-17487-13 | L38: Korea United Pharm. Inc. | M38: Korea | N38: Lọ | O38: 263000 | P38: 400 | Q38: =ROUNDDOWN((P38*30%),0) -> 120 | R38: 449/QĐ-BVĐN | V38: CÔNG TY TNHH BIONAM
A39: 35 | B39: 362 | C39: Nhóm 1 | D39: Doxorubicin "Ebewe" | E39: Doxorubicin | F39: 2mg/ml | G39: Tiêm truyền tĩnh mạch | H39: Dung dịch đậm đặc để pha dung dịch tiêm truyền | I39: Hộp 1 lọ 5ml | J39: 24 tháng | K39: 900114412423 | L39: Fareva Unterach GmbH | M39: Áo | N39: Lọ | O39: 184691 | P39: 200 | Q39: =ROUNDDOWN((P39*30%),0) -> 60 | R39: 449/QĐ-BVĐN | S39: =VLOOKUP(B39,[1]GỐC!$B:$F,5,0) -> Quỹ bảo hiểm y tế thanh toán 50% đối với dạng liposome; thanh toán 100% đối với các dạng khác. | V39: CÔNG TY CỔ PHẦN DƯỢC LIỆU TRUNG ƯƠNG 2
A40: 36 | B40: 369 | C40: Nhóm 2 | D40: Hytinon | E40: Hydroxyurea (Hydroxycarbamid) | F40: 500mg | G40: Uống | H40: Viên nang cứng | I40: Hộp 100 viên, túi nhôm x 10 vỉ x 10 viên nang cứng | J40: 36 tháng | K40: 880114031225 (SĐK cũ: VN-22158-19) | L40: Korea United Pharm.Inc. | M40: Hàn Quốc | N40: Viên | O40: 4800 | P40: 70050 | Q40: =ROUNDDOWN((P40*30%),0) -> 21015 | R40: 449/QĐ-BVĐN | V40: CÔNG TY CỔ PHẦN VILLA-VILLA
A41: 37 | B41: 373 | C41: Nhóm 1 | D41: Spectrila | E41: L-asparaginase | F41: 10.000 I.U | G41: Tiêm truyền | H41: Bột đông khô pha tiêm truyền | I41: Hộp 1 lọ x 10.000 I.U L-asparaginase | J41: 48 tháng | K41: 3986/QLD-KD 2506/QLD-KD 1865/QLD-KD | L41: - Cơ sở sản xuất: LYOCONTRACT GmbH - SHGP, đóng gói thứ cấp, xuất xưởng: Medac Gesellschaft fur klinische Spezialpraparate mbH | M41: - Cơ sở sản xuất: Đức - SHGP,đóng gói thứ cấp, xuất xưởng: Đức | N41: Lọ | O41: 5302000 | P41: 64 | Q41: =ROUNDDOWN((P41*30%),0) -> 19 | R41: 449/QĐ-BVĐN | S41: =VLOOKUP(B41,[1]GỐC!$B:$F,5,0) -> Quỹ bảo hiểm y tế thanh toán 50% đối với dạng L-asparaginase erwinia; thanh toán 100% đối với các dạng khác. | V41: CÔNG TY TNHH DƯỢC PHẨM VIỆT - PHÁP
A42: 38 | B42: 415 | C42: Nhóm 5 | D42: Thymogam | E42: Anti thymocyte globulin | F42: 250mg/5ml | G42: Tiêm truyền | H42: Dung dịch tiêm truyền | I42: Hộp 1 lọ 5ml | J42: 24 tháng | K42: 622/QLD-KD | L42: BHARAT SERUMS AND VACCINES LIMITED | M42: Ấn Độ | N42: Lọ | O42: 3000000 | P42: 39 | Q42: =ROUNDDOWN((P42*30%),0) -> 11 | R42: 449/QĐ-BVĐN | V42: CÔNG TY CỔ PHẦN MEDCOMTECH
A43: 39 | B43: 419 | C43: Nhóm 5 | D43: Simulect | E43: Basiliximab | F43: 20mg | G43: Tiêm | H43: Bột pha tiêm | I43: Hộp 1 lọ bột pha tiêm | J43: 36 tháng | K43: 800410322725 | L43: Cơ sở sản xuất và đóng gói cấp 1: Patheon Italia S.p.A; Cơ sở sản xuất ống dung môi, đóng gói cấp 2 và xuất xưởng: Delpharm Dijon | M43: Cơ sở sản xuất và đóng gói cấp 1: Ý; Cơ sở sản xuất ống dung môi, đóng gói cấp 2 và xuất xưởng: Pháp | N43: Lọ | O43: 29682123 | P43: 36 | Q43: =ROUNDDOWN((P43*30%),0) -> 10 | R43: 449/QĐ-BVĐN | S43: =VLOOKUP(B43,[1]GỐC!$B:$F,5,0) -> Quỹ bảo hiểm y tế thanh toán 50%. | V43: CÔNG TY CỔ PHẦN DƯỢC LIỆU TRUNG ƯƠNG 2
A44: 40 | B44: 422 | C44: Nhóm 1 | D44: Myfortic 360mg | E44: Mycophenolat | F44: 360mg | G44: Uống | H44: Viên nén bao tan trong ruột | I44: Hộp 12 vỉ x 10 viên | J44: 36 tháng | K44: 400114430523 | L44: Cơ sở sản xuất: Novartis Pharma Produktions GmbH; Cơ sở đóng gói và xuất xưởng: Lek d.d., PE Proizvodnja Lendava | M44: Cơ sở sản xuất: Đức; Cơ sở đóng gói và xuất xưởng: Slovenia | N44: Viên | O44: 43621 | P44: 33000 | Q44: =ROUNDDOWN((P44*30%),0) -> 9900 | R44: 449/QĐ-BVĐN | V44: CÔNG TY CỔ PHẦN DƯỢC LIỆU TRUNG ƯƠNG 2
A45: 41 | B45: 434 | C45: Nhóm 4 | D45: Pakicen 250/25 | E45: Levodopa + carbidopa | F45: 25mg+250mg | G45: Uống | H45: Viên nén | I45: Hộp 03 vỉ x 10 viên, Hộp 05 vỉ x 10 viên, Hộp 10 vỉ x 10 viên | J45: 36 tháng | K45: 893110272625 | L45: Công ty Cổ phần Medcen | M45: Việt Nam | N45: Viên | O45: 3466 | P45: 66000 | Q45: =ROUNDDOWN((P45*30%),0) -> 19800 | R45: 449/QĐ-BVĐN | V45: CÔNG TY TNHH THƯƠNG MẠI DƯỢC PHẨM MINH TÍN
A46: 42 | B46: 444 | C46: Nhóm 4 | D46: Furemin | E46: Sắt (III) hydroxyd polymaltose | F46: 50mg/5ml | G46: Uống | H46: Sirô | I46: Hộp 20 ống x 10ml | J46: 24 tháng | K46: 893100084825 | L46: Công ty cổ phần dược phẩm Thành Phát | M46: Việt Nam | N46: Ống | O46: 7489 | P46: 2770 | Q46: =ROUNDDOWN((P46*30%),0) -> 831 | R46: 449/QĐ-BVĐN | V46: CÔNG TY TNHH THƯƠNG MẠI DƯỢC PHẨM ENDOPHACO
A47: 43 | B47: 450 | C47: Nhóm 2 | D47: Fegem-100 | E47: Sắt (III) hydroxyd polymaltose + acid folic | F47: 100mg + 0,35mg | G47: Uống | H47: Viên nén nhai | I47: Hộp 10 vỉ xé x 10 viên | J47: 24 tháng | K47: 890100046225 (VN-14829-12) | L47: Torrent Pharmaceuticals Ltd. | M47: Ấn Độ | N47: Viên | O47: 2625 | P47: 10000 | Q47: =ROUNDDOWN((P47*30%),0) -> 3000 | R47: 449/QĐ-BVĐN | V47: CÔNG TY TNHH DƯỢC PHẨM VÀ TRANG THIẾT BỊ Y TẾ HOÀNG ĐỨC
A48: 44 | B48: 463 | C48: Nhóm 1 | D48: Albunorm 20% | E48: Albumin | F48: 10g/50ml; 100ml | G48: Tiêm truyền | H48: Dung dịch tiêm truyền | I48: Hộp 1 lọ x 100ml | J48: 36 tháng | K48: "400410646324 (QLSP-1129-18)" | L48: Cơ sở sản xuất bán thành phẩm đóng gói cấp 1 và xuất xưởng lô: Octapharma Produktionsgesellschaft Deutschland mbH; Cơ sở đóng gói cấp 2: Octapharma Dessau GmbH | M48: Germany | N48: Lọ | O48: 1493000 | P48: 905 | Q48: =ROUNDDOWN((P48*30%),0) -> 271 | R48: 449/QĐ-BVĐN | S48: =VLOOKUP(B48,[1]GỐC!$B:$F,5,0) -> Quỹ bảo hiểm y tế thanh toán trong trường hợp: Nồng độ albumin máu ≤ 2,5 g/dl hoặc sốc hoặc hội chứng suy hô hấp tiến triển; thanh toán 70%. | V48: CÔNG TY TNHH BÌNH VIỆT ĐỨC
A49: 45 | B49: 484 | C49: Nhóm 2 | D49: Epokine Prefilled injection 2000Units/0,5ml | E49: Erythropoietin | F49: 2000IU/0,5ml | G49: Tiêm | H49: Dung dịch tiêm | I49: Hộp 6 bơm tiêm x 0,5ml | J49: 24 tháng | K49: 880410110624 | L49: HK inno.N Corporation | M49: Hàn Quốc | N49: Bơm tiêm | O49: 175000 | P49: 17020 | Q49: =ROUNDDOWN((P49*30%),0) -> 5106 | R49: 449/QĐ-BVĐN | V49: CÔNG TY TNHH DƯỢC PHẨM ĐÔNG ĐÔ
A50: 46 | B50: 484 | C50: Nhóm 2 | D50: Epokine Prefilled Injection 4000IU/0,4ml | E50: Erythropoietin | F50: 4000IU/0,4ml | G50: Tiêm | H50: Dung dịch tiêm | I50: Hộp 6 bơm tiêm x 0,4ml | J50: 24 tháng | K50: QLSP-0666-13 | L50: HK inno.N Corporation | M50: Hàn Quốc | N50: Bơm tiêm | O50: 274500 | P50: 3520 | Q50: =ROUNDDOWN((P50*30%),0) -> 1056 | R50: 449/QĐ-BVĐN | V50: CÔNG TY TNHH DƯỢC PHẨM ĐÔNG ĐÔ
A51: 47 | B51: 485 | C51: Nhóm 5 | D51: NEUTROMAX | E51: Filgrastim | F51: 300mcg | G51: Tiêm | H51: Dung dịch tiêm | I51: Hộp 1 lọ 1ml dung dịch tiêm | J51: 24 | K51: QLSP-0804-14 | L51: BIO SIDUS S.A. | M51: Argentina | N51: Lọ | O51: 142277 | P51: 1410 | Q51: =ROUNDDOWN((P51*30%),0) -> 423 | R51: 449/QĐ-BVĐN | V51: CÔNG TY TNHH DƯỢC PHẨM TỨ HƯNG
A52: 48 | B52: 506 | C52: Nhóm 1 | D52: Telassmo 40 mg/5 mg | E52: Amlodipin + telmisartan | F52: 40mg + 5mg | G52: Uống | H52: Viên nén | I52: Hộp 4 vỉ x 7 viên | J52: 36 tháng | K52: 383110326825 | L52: KRKA, D.D., Novo Mesto | M52: Slovenia | N52: Viên | O52: 10395 | P52: 105000 | Q52: =ROUNDDOWN((P52*30%),0) -> 31500 | R52: 449/QĐ-BVĐN | V52: CÔNG TY CỔ PHẦN Y DƯỢC VSK
A53: 49 | B53: 540 | C53: Nhóm 3 | D53: Nifedipin Hasan 20 Retard | E53: Nifedipin | F53: 20mg | G53: Uống | H53: viên nén bao phim tác dụng kéo dài | I53: Hộp 3 vỉ, 10 vỉ x 10 viên | J53: 36 tháng | K53: 893110458024 | L53: Công ty TNHH Hasan - Dermapharm | M53: Việt Nam | N53: Viên | O53: 672 | P53: 7420 | Q53: =ROUNDDOWN((P53*30%),0) -> 2226 | R53: 449/QĐ-BVĐN | V53: CÔNG TY TNHH DƯỢC PHẨM VIỆT ĐỨC
...

Sheet Phụ lục II
A1: Phụ lục II: HƯỚNG DẪN THỰC HIỆN DANH MỤC THUỐC BỔ SUNG TẠI BỆNH VIỆN ĐÀ NẴNG NĂM 2026
A2: (Đính kèm Thông báo số /TB-BVĐN ngày / /2026 của Bệnh viện Đà Nẵng)
A4: STT | B4: Nội dung (viết tắt) | C4: Hướng dẫn
A5: 1 | B5: Phụ lục I | C5: Căn cứ Quyết định số 165/QĐ-TTMS ngày 29 tháng 12 năm 2025 của Giám đốc Trung tâm mua sắm tập trung thuốc quốc gia về việc phê duyệt kết quả lựa chọn nhà thầu qua mạng gói thầu cung cấp thuốc cho các cơ sở y tế giai đoạn 2024-2026 đợt 3 (Mã hiệu: ĐTTT.2025.1) thuộc Kế hoạch lựa chọn nhà thầu cung cấp thuốc thuộc danh mục đấu thầu tập trung cấp quốc gia giai doạn 2024-2026 do Trung tâm Mua sắm tập trung thuốc Quốc gia thực hiện đợt 3, trong đó: - Danh mục thuốc gồm 01 thuốc, sử dụng cho Bệnh viện Đà Nẵng. - Loại hợp đồng: Hợp đồng theo đơn giá cố định. - Thời gian thực hiện hợp đồng: 12 tháng. - Nguồn vốn: Nguồn quỹ bảo hiểm y tế, ngân sách nhà nước, nguồn thu từ dịch vụ khám bệnh, chữa bệnh và nguồn thu hợp pháp khác của cơ sở y tế. Căn cứ Quyết định số 449/QĐ-BVĐN ngày 30 tháng 03 năm 2026 của Giám đốc Bệnh viện Đà Nẵng về việc phê duyệt kết quả lựa chọn nhà thầu qua mạng Gói thầu thuốc generic (Gồm 161 danh mục) thuộc kế hoạch lựa chọn nhà thầu dự toán mua sắm Mua bổ sung thuốc generic 12 tháng cho Bệnh viện Đà Nẵng năm 2026 thuộc dự toán mua sắm Mua bổ sung thuốc generic 12 tháng cho Bệnh viện Đà Nẵng năm 2026 - Danh mục thuốc gồm 119 thuốc, sử dụng cho Bệnh viện Đà Nẵng. - Loại hợp đồng: Hợp đồng theo đơn giá cố định. - Thời gian thực hiện hợp đồng: 12 tháng từ ngày hợp đồng có hiệu lực. - Nguồn vốn: Nguồn ngân sách nhà nước, nguồn thu hoạt động sự nghiệp của Bệnh viện Đà Nẵng.
A6: 2 | B6: Thông tư số 20/2022/TT-BYT ngày 31/12/2022 (TT20) | C6: - Nội dung Thông tư số 20/2022/TT-BYT ngày 31 tháng 12 năm 2022 của Bộ Y tế ban hành danh mục và tỷ lệ, điều kiện thanh toán đối với thuốc hóa dược, sinh phẩm, thuốc phóng xạ và chất đánh dấu thuộc phạm vi được hưởng của người tham gia bảo hiểm y tế. - Thuốc đánh theo Số thứ tự của hoạt chất, đường dùng, dạng dùng theo Thông tư số 20/2022/TT-BYT: thanh toán theo nguồn Quỹ Bảo hiểm y tế.
A7: 3 | B7: Lưu ý kê đơn
A8: 3.1 | B8: Biên bản hội chẩn (BBHC) | C8: Phải được hội chẩn trước khi sử dụng, trừ trường hợp cấp cứu thì hoàn thiện BBHC sau. Đối với thuốc kháng sinh có lưu ý BBHC, Quỹ bảo hiểm y tế thanh toán khi thực hiện đúng quy trình hội chẩn khi kê đơn theo quy định về Hướng dẫn thực hiện quản lý sử dụng kháng sinh trong bệnh viện của Bộ Y tế
A9: 3.2 | B9: Duyệt BGĐ | C9: Phải duyệt Ban giám đốc trước khi sử dụng
A10: 3.3 | B10: Thuốc có quy định điều kiện, tỉ lệ thanh toán | C10: Chỉ được thanh toán BHYT đối với các trường hợp kê đơn đúng theo quy định điều kiện, tỉ lệ thanh toán
C11: - "Ngoài TT20": Thuốc có hoạt chất, đường dùng không thuộc Thông tư số 20/2022/TT-BYT: thanh toán theo nguồn khác không phải nguồn Bảo hiểm y tế như Nguồn kinh phí từ thu hoạt động sự nghiệp, nguồn tài chính hợp pháp được sử dụng theo quy định của pháp luật.
